Workbook

Sheet global_comparison
A1: Location description | B1: location | C1: subgroup | D1: area_km2 | E1: co2_cons_mol_yr | F1: co2_cons_mol_km2_yr | G1: tds_ppm | H1: annual_discharge_km3_yr | I1: runoff_mm_yr | J1: tds_mg_l | K1: tss_mg_l | L1: Na_mM | M1: K_mM | N1: Ca_mM | O1: Mg_mM | P1: Cl_mM | Q1: SO4_mM | R1: HCO3_mM | S1: SiO2_mM | T1: Sr_mM | U1: Sr_ratio | V1: Paper
A2: Irrawady | C2: major | D2: 410000 | E2: =VLOOKUP($A2,Sheet2!$A$28:$M$79,6,FALSE) -> 832000000000 | F2: =E2/D2 -> 2029268.3 | H2: 486 | I2: 1185 | J2: 201 | K2: 535 | L2: 1304 | M2: 51 | N2: 250 | O2: 247 | P2: 514 | Q2: 52 | R2: 1967 | S2: 167 | V2: Gaillardet et al 1999
A3: Purari | C3: major | D3: 30600 | E3: =VLOOKUP($A3,Sheet2!$A$28:$M$79,6,FALSE) -> 37000000000 | F3: =E3/D3 -> 1209150.3 | H3: 84.13 | I3: 2749 | J3: 126 | K3: 951 | L3: 139 | M3: 26 | N3: 515 | O3: 107 | P3: 34 | Q3: 25 | R3: 1328 | S3: 230 | V3: Gaillardet et al 1999
A4: Narmada | C4: major | D4: 102000 | E4: =VLOOKUP($A4,Sheet2!$A$28:$M$79,6,FALSE) -> 95000000000 | F4: =E4/D4 -> 931372.55 | H4: 39 | I4: 382 | J4: 285 | K4: 3071 | L4: 1522 | N4: 625 | O4: 790 | P4: 486 | Q4: 52 | R4: 2869 | S4: 150 | V4: Gaillardet et al 1999
A5: Sepik | C5: major | D5: 78700 | E5: =VLOOKUP($A5,Sheet2!$A$28:$M$79,6,FALSE) -> 72000000000 | F5: =E5/D5 -> 914866.58 | H5: 120 | I5: 1525 | J5: 114 | K5: 68 | L5: 152 | M5: 10 | N5: 388 | O5: 165 | P5: 14 | Q5: 47 | R5: 1205 | S5: 208 | V5: Gaillardet et al 1999
A6: Rhone | C6: major | D6: 95600 | E6: =VLOOKUP($A6,Sheet2!$A$28:$M$79,6,FALSE) -> 4700000000 | F6: =E6/D6 -> 49163.18 | H6: 54 | I6: 565 | J6: 339 | K6: 500 | L6: 491 | M6: 54 | N6: 1770 | O6: 267 | P6: 640 | Q6: 479 | R6: 2885 | S6: 67 | T6: 5.94 | U6: 0.7087 | V6: Gaillardet et al 1999
A7: Cauveri | C7: major | D7: 88000 | E7: =VLOOKUP($A7,Sheet2!$A$28:$M$79,6,FALSE) -> 56000000000 | F7: =E7/D7 -> 636363.64 | H7: 21 | I7: 239 | J7: 396 | L7: 2609 | M7: 141 | N7: 700 | O7: 988 | P7: 1429 | Q7: 333 | R7: 2902 | S7: 317 | T7: 3.62 | U7: 0.713 | V7: Gaillardet et al 1999
A8: Ganges | C8: major | D8: 1050000 | E8: =VLOOKUP($A8,Sheet2!$A$28:$M$79,6,FALSE) -> 471000000000 | F8: =E8/D8 -> 448571.43 | H8: 493 | I8: 470 | J8: 182 | K8: 1100 | L8: 417 | M8: 67 | N8: 580 | O8: 267 | P8: 143 | Q8: 83 | R8: 1951 | S8: 128 | T8: 1.02 | U8: 0.7249 | V8: Gaillardet et al 1999
A9: Wisla | C9: major | D9: 198000 | H9: 32.5 | I9: 164 | J9: 583 | K9: 79 | L9: 2696 | M9: 126 | N9: 2250 | O9: 535 | P9: 4200 | Q9: 792 | R9: 3115 | T9: 7.94 | U9: 0.7094 | V9: Gaillardet et al 1999
A10: Rhine | C10: major | D10: 224000 | E10: =VLOOKUP($A10,Sheet2!$A$28:$M$79,6,FALSE) -> 14000000000 | F10: =E10/D10 -> 62500 | H10: 69.4 | I10: 310 | J10: 600 | L10: 3957 | M10: 164 | N10: 2013 | O10: 469 | P10: 4943 | Q10: 771 | R10: 2590 | S10: 87 | T10: 6.23 | U10: 0.7092 | V10: Gaillardet et al 1999
A11: Brahmaputra | C11: major | D11: 580000 | E11: =VLOOKUP($A11,Sheet2!$A$28:$M$79,6,FALSE) -> 87000000000 | F11: =E11/D11 -> 150000 | H11: 510 | I11: 879 | J11: 101 | K11: 1060 | L11: 91 | M11: 100 | N11: 350 | O11: 156 | P11: 31 | Q11: 104 | R11: 951 | S11: 130 | T11: 0.67 | U11: 0.7197 | V11: Gaillardet et al 1999
A12: Magdalena | C12: major | D12: 235000 | E12: =VLOOKUP($A12,Sheet2!$A$28:$M$79,6,FALSE) -> 15000000000 | F12: =E12/D12 -> 63829.787 | H12: 237 | I12: 1009 | J12: 118 | K12: 928 | L12: 361 | M12: 49 | N12: 375 | O12: 136 | P12: 383 | Q12: 150 | R12: 808 | S12: 210 | V12: Gaillardet et al 1999
A13: Danube | C13: major | D13: 817000 | H13: 207 | I13: 253 | J13: 428 | K13: 313 | L13: 739 | M13: 51 | N13: 1473 | O13: 1117 | P13: 1509 | Q13: 660 | R13: 3328 | S13: 69 | T13: 2.76 | U13: 0.7089 | V13: Gaillardet et al 1999
A14: Xijiang | C14: major | D14: 437000 | E14: =VLOOKUP($A14,Sheet2!$A$28:$M$79,6,FALSE) -> 24000000000 | F14: =E14/D14 -> 54919.908 | H14: 363 | I14: 831 | J14: 161 | K14: 190 | L14: 117 | M14: 31 | N14: 810 | O14: 198 | P14: 91 | Q14: 85 | R14: 1639 | S14: 142 | T14: 1.27 | U14: 0.71068 | V14: Gaillardet et al 1999
A15: Weser | C15: major | D15: 46000 | H15: 10.6 | I15: 230 | J15: 2463 | K15: 31 | L15: 24 957 | M15: 1077 | N15: 1400 | O15: 6214 | P15: 35 229 | Q15: 2448 | R15: 2754 | S15: 67 | T15: 8.23 | U15: 0.7089 | V15: Gaillardet et al 1999
A16: Kikori | C16: major | D16: 13200 | E16: =VLOOKUP($A16,Sheet2!$A$28:$M$79,6,FALSE) -> 2500000000 | F16: =E16/D16 -> 189393.94 | H16: 40.06 | I16: 3035 | J16: 177 | L16: 57 | M16: 5 | N16: 933 | O16: 165 | P16: 9 | Q16: 11 | R16: 2049 | S16: 133 | V16: Gaillardet et al 1999
A17: Uruguay | C17: major | D17: 240000 | E17: =VLOOKUP($A17,Sheet2!$A$28:$M$79,6,FALSE) -> 38900000000 | F17: =E17/D17 -> 162083.33 | H17: 145 | I17: 604 | J17: 60 | K17: 76 | L17: 123 | M17: 35 | N17: 148 | O17: 99 | P17: 57 | Q17: 52 | R17: 426 | S17: 250 | V17: Gaillardet et al 1999
A18: Krishna | C18: major | D18: 259000 | E18: =VLOOKUP($A18,Sheet2!$A$28:$M$79,6,FALSE) -> 41000000000 | F18: =E18/D18 -> 158301.16 | H18: 30 | I18: 116 | J18: 317 | K18: 2130 | L18: 1848 | M18: 77 | N18: 688 | O18: 556 | P18: 1057 | Q18: 656 | R18: 2049 | S18: 83 | V18: Gaillardet et al 1999
A19: N. Dvina | C19: major | D19: 348000 | E19: =VLOOKUP($A19,Sheet2!$A$28:$M$79,6,FALSE) -> 9000000000 | F19: =E19/D19 -> 25862.069 | H19: 110 | I19: 316 | J19: 173 | K19: 43 | L19: 217 | M19: 26 | N19: 750 | O19: 296 | P19: 154 | Q19: 403 | R19: 1361 | S19: 38 | V19: Gaillardet et al 1999
A20: Kuskokwin | C20: major | D20: 123000 | E20: =VLOOKUP($A20,Sheet2!$A$28:$M$79,6,FALSE) -> 12300000000 | F20: =E20/D20 -> 100000 | H20: 59.9 | I20: 487 | J20: 145 | K20: 116 | L20: 96 | M20: 20 | N20: 605 | O20: 226 | P20: 19 | Q20: 147 | R20: 1469 | S20: 127 | T20: 1.06 | U20: 0.709 | V20: Gaillardet et al 1999
A21: Limpopo | C21: major | D21: 440000 | E21: =VLOOKUP($A21,Sheet2!$A$28:$M$79,6,FALSE) -> 42400000000 | F21: =E21/D21 -> 96363.636 | H21: 26 | I21: 59 | J21: 238 | K21: 1269 | L21: 896 | M21: 118 | N21: 483 | O21: 506 | P21: 406 | Q21: 54 | R21: 2361 | S21: 295 | V21: Gaillardet et al 1999
A22: Ob | C22: major | D22: 2990000 | E22: =VLOOKUP($A22,Sheet2!$A$28:$M$79,6,FALSE) -> 57000000000 | F22: =E22/D22 -> 19063.545 | H22: 404 | I22: 135 | J22: 126 | K22: 40 | L22: 230 | M22: 26 | N22: 465 | O22: 210 | P22: 186 | Q22: 89 | R22: 1279 | S22: 43 | V22: Gaillardet et al 1999
A23: Salween | C23: major | D23: 325000 | H23: 211 | I23: 649 | J23: 306 | L23: 435 | M23: 26 | N23: 1150 | O23: 658 | P23: 571 | Q23: 10 | R23: 3475 | V23: Gaillardet et al 1999
A24: Don | C24: major | D24: 420000 | E24: =VLOOKUP($A24,Sheet2!$A$28:$M$79,6,FALSE) -> 48000000000 | F24: =E24/D24 -> 114285.71 | H24: 28.9 | I24: 69 | J24: 829 | K24: 80 | L24: 6348 | M24: 26 | N24: 2073 | O24: 1481 | P24: 4200 | Q24: 2240 | R24: 3295 | S24: 5 | V24: Gaillardet et al 1999
A25: Parana | C25: major | D25: 2780000 | E25: =VLOOKUP($A25,Sheet2!$A$28:$M$79,6,FALSE) -> 263000000000 | F25: =E25/D25 -> 94604.317 | H25: 568 | I25: 204 | J25: 86 | K25: 139 | L25: 231 | M25: 94 | N25: 173 | O25: 86 | P25: 185 | Q25: 21 | R25: 690 | S25: 285 | T25: 0.52 | U25: 0.7139 | V25: Gaillardet et al 1999
A26: Columbia | C26: major | D26: 669000 | E26: =VLOOKUP($A26,Sheet2!$A$28:$M$79,6,FALSE) -> 61000000000 | F26: =E26/D26 -> 91180.867 | H26: 236 | I26: 353 | J26: 115 | K26: 64 | L26: 217 | M26: 28 | N26: 450 | O26: 206 | P26: 86 | Q26: 115 | R26: 1033 | S26: 150 | T26: 0.98 | U26: 0.7121 | V26: Gaillardet et al 1999
A27: Mississippi | C27: major | D27: 2980000 | E27: =VLOOKUP($A27,Sheet2!$A$28:$M$79,6,FALSE) -> 199000000000 | F27: =E27/D27 -> 66778.523 | H27: 580 | I27: 195 | J27: 216 | K27: 862 | L27: 478 | M27: 72 | N27: 850 | O27: 366 | P27: 294 | Q27: 266 | R27: 1902 | S27: 127 | T27: 1.71 | U27: 0.7102 | V27: Gaillardet et al 1999
A28: Huanghe | C28: major | D28: 752000 | E28: =VLOOKUP($A28,Sheet2!$A$28:$M$79,6,FALSE) -> 62000000000 | F28: =E28/D28 -> 82446.809 | H28: 41 | I28: 55 | J28: 460 | K28: 26 900 | L28: 2370 | M28: 105 | N28: 1175 | O28: 848 | P28: 1563 | Q28: 696 | R28: 3361 | S28: 128 | T28: 13 | U28: 0.71111 | V28: Gaillardet et al 1999
A29: Changjiang | C29: major | D29: 1810000 | E29: =VLOOKUP($A29,Sheet2!$A$28:$M$79,6,FALSE) -> 107000000000 | F29: =E29/D29 -> 59116.022 | H29: 928 | I29: 513 | J29: 221 | K29: 520 | L29: 222 | M29: 36 | N29: 973 | O29: 292 | P29: 151 | Q29: 164 | R29: 2311 | S29: 108 | T29: 2.42 | U29: 0.71071 | V29: Gaillardet et al 1999
A30: Orinoco | C30: major | D30: 1100000 | E30: =VLOOKUP($A30,Sheet2!$A$28:$M$79,6,FALSE) -> 76000000000 | F30: =E30/D30 -> 69090.909 | H30: 1135 | I30: 1032 | J30: 25 | K30: 132 | L30: 64 | M30: 17 | N30: 65 | O30: 27 | P30: 25 | Q30: 24 | R30: 164 | S30: 105 | T30: 0.21 | U30: 0.7183 | V30: Gaillardet et al 1999
A31: Nelson | C31: major | D31: 1130000 | E31: =VLOOKUP($A31,Sheet2!$A$28:$M$79,6,FALSE) -> 43000000000 | F31: =E31/D31 -> 38053.097 | H31: 89.3 | I31: 79 | J31: 236 | L31: 696 | M31: 59 | N31: 823 | O31: 457 | P31: 486 | Q31: 271 | R31: 2115 | S31: 23 | T31: 0.86 | U31: 0.7146 | V31: Gaillardet et al 1999
A32: Amazon | C32: major | D32: 6110000 | E32: =VLOOKUP($A32,Sheet2!$A$28:$M$79,6,FALSE) -> 320000000000 | F32: =E32/D32 -> 52373.159 | H32: 6590 | I32: 1078 | J32: 44 | K32: 182 | L32: 80 | M32: 21 | N32: 135 | O32: 37 | P32: 61 | Q32: 47 | R32: 344 | S32: 115 | T32: 0.19 | U32: 0.71148 | V32: Gaillardet et al 1999
A33: Mackenzie | C33: major | D33: 1790000 | E33: =VLOOKUP($A33,Sheet2!$A$28:$M$79,6,FALSE) -> 61000000000 | F33: =E33/D33 -> 34078.212 | H33: 308 | I33: 172 | J33: 209 | K33: 134 | L33: 330 | M33: 26 | N33: 890 | O33: 337 | P33: 226 | Q33: 369 | R33: 1803 | S33: 50 | T33: 2 | U33: 0.711 | V33: Gaillardet et al 1999
A34: Indus | C34: major | D34: 916000 | E34: =VLOOKUP($A34,Sheet2!$A$28:$M$79,6,FALSE) -> 54000000000 | F34: =E34/D34 -> 58951.965 | H34: 90 | I34: 98 | J34: 302 | K34: 2778 | L34: 1370 | M34: 112 | N34: 958 | O34: 374 | P34: 931 | Q34: 436 | R34: 2130 | S34: 233 | T34: 3.69 | U34: 0.711 | V34: Gaillardet et al 1999
A35: Kolima | C35: major | D35: 660000 | E35: =VLOOKUP($A35,Sheet2!$A$28:$M$79,6,FALSE) -> 29000000000 | F35: =E35/D35 -> 43939.394 | H35: 132 | I35: 200 | J35: 74 | K35: 126 | L35: 122 | M35: 46 | N35: 270 | O35: 99 | P35: 80 | Q35: 147 | R35: 570 | S35: 67 | V35: Gaillardet et al 1999
A36: Fraser | C36: major | D36: 220000 | E36: =VLOOKUP($A36,Sheet2!$A$28:$M$79,6,FALSE) -> 9400000000 | F36: =E36/D36 -> 42727.273 | H36: 112 | I36: 509 | J36: 92 | K36: 175 | L36: 126 | M36: 18 | N36: 443 | O36: 148 | P36: 69 | Q36: 85 | R36: 841 | S36: 91 | T36: 0.795 | U36: 0.7112 | V36: Gaillardet et al 1999
A37: Khatanga | C37: major | D37: 364000 | E37: =VLOOKUP($A37,Sheet2!$A$28:$M$79,6,FALSE) -> 15400000000 | F37: =E37/D37 -> 42307.692 | H37: 85.3 | I37: 234 | J37: 96 | K37: 17 | L37: 422 | M37: 26 | N37: 313 | O37: 148 | P37: 357 | Q37: 58 | R37: 785 | S37: 53 | V37: Gaillardet et al 1999
A38: Shatt el arab | C38: major | D38: 541000 | E38: =VLOOKUP($A38,Sheet2!$A$28:$M$79,6,FALSE) -> 37000000000 | F38: =E38/D38 -> 68391.867 | H38: 45.8 | I38: 85 | J38: 400 | K38: 2295 | L38: 1348 | M38: 77 | N38: 1300 | O38: 905 | P38: 914 | Q38: 760 | R38: 2951 | S38: 115 | V38: Gaillardet et al 1999
A39: Niger | C39: major | D39: 1200000 | E39: =VLOOKUP($A39,Sheet2!$A$28:$M$79,6,FALSE) -> 35500000000 | F39: =E39/D39 -> 29583.333 | H39: 154.1 | I39: 128 | J39: 59 | K39: 260 | L39: 78 | M39: 28 | N39: 138 | O39: 78 | P39: 26 | Q39: 5 | R39: 549 | S39: 233 | T39: 0.25 | U39: 0.714 | V39: Gaillardet et al 1999
A40: Murray Darling | C40: major | D40: 1060000 | E40: =VLOOKUP($A40,Sheet2!$A$28:$M$79,6,FALSE) -> 25000000000 | F40: =E40/D40 -> 23584.906 | H40: 23.6 | I40: 22 | J40: 453 | K40: 1271 | L40: 4391 | M40: 154 | N40: 525 | O40: 700 | P40: 4886 | Q40: 396 | R40: 1541 | S40: 83 | U40: 0.7138 | V40: Gaillardet et al 1999
...

Sheet Sheet2
A11: Moore et al 2025 | V11: Goldsmith et al 2010
A12: Watershed | B12: degrees | C12: degrees | D12: yr−1 | E12: °C | F12: cm yr−1 | G12: km2 | H12: degrees | I12: m asl | J12: μg g−1 | K12: μg g−1 | L12: tons km−2 yr−1 | M12: tons km−2 yr−1 | N12: – | O12: – | P12: – | Q12: – | R12: tons km−2 yr−1 | S12: μg cm−3 | V12: River | W12: Area km² | X12: Qwet | Y12: Qdry | Z12: Qann mean m³/s | AA12: Specific Q L/s/km² | AB12: Runoff mm/yr
A13: S1 | B13: 18.1332 | C13: −66.9362 | D13: 208 | E13: 23.7 | F13: 106 | G13: 12.8 | H13: 31 | I13: 517 | J13: 46.9 ± 1.6 | K13: 76.7 ± 1.7 | L13: 49.8 ± 1.7 | M13: 81.4 ± 1.8 | N13: 0.37 ± 0.14 | O13: 0.26 ± 0.17 | P13: 0.58 ± 0.36 | Q13: 0.06 ± 0.06 | R13: 108 ± 12 | S13: 102 ± 12 | V13: Geneva River DS | W13: 21 | X13: 1.3 | Y13: 0.7 | Z13: 1.1 | AA13: 52.4 | AB13: 1652
A14: S3a | B14: 18.0636 | C14: −66.9133 | D14: 127 | E14: 24.6 | F14: 20 | G14: 4.8 | H14: 21 | I14: 189 | J14: 155 ± 5 | K14: 221 ± 5 | L14: 31.5 ± 1.1 | M14: 45.0 ± 1.1 | N14: 0.75 ± 0.01 | O14: 0.84 ± 0.01 | P14: 2.99 ± 0.20 | Q14: 0.92 ± 0.08 | R14: 25 ± 3 | S14: 123 ± 13 | V14: Rosalie River | W14: 31 | X14: 3.4 | Y14: 1.9 | Z14: 2.9 | AA14: 93.5 | AB14: 2950
A15: S4a | B15: 18.057 | C15: −66.9125 | D15: 125 | E15: 24.6 | F15: 19 | G15: 0.3 | H15: 21 | I15: 174 | J15: 156 ± 4 | K15: 236 ± 4 | L15: 29.9 ± 0.8 | M15: 45.1 ± 0.9 | N15: 0.85 ± 0.04 | O15: 0.91 ± 0.03 | P15: 5.53 ± 1.55 | Q15: 1.81 ± 0.49 | R15: 22 ± 3 | S15: 116 ± 13 | V15: La Ronde River | W15: 3 | X15: 0.19 | Y15: 0.07 | Z15: 0.15 | AA15: 50 | AB15: 1577
A16: S5 | B16: 18.1129 | C16: −66.9563 | D16: 165 | E16: 24.4 | F16: 48 | G16: 3.2 | H16: 26 | I16: 368 | J16: 118 ± 4 | K16: 166 ± 4 | L16: 57.1 ± 2.0 | M16: 80.5 ± 2.1 | N16: 0.55 ± 0.08 | O16: 0.66 ± 0.08 | P16: 1.20 ± 0.37 | Q16: 0.39 ± 0.11 | R16: 47 ± 5 | S16: 97 ± 10 | V16: Mahaut River | W16: 0.8 | X16: 0.02 | Y16: 0.003 | Z16: 0.0143 | AA16: 17.9 | AB16: 565
A17: S6 | B17: 18.1174 | C17: −66.9623 | D17: 169 | E17: 24.3 | F17: 53 | G17: 2.2 | H17: 27 | I17: 400 | J17: 95.6 ± 4.5 | K17: 137 ± 5 | L17: 50.3 ± 2.4 | M17: 72.3 ± 2.4 | N17: 0.66 ± 0.01 | O17: 0.76 ± 0.01 | P17: 1.96 ± 0.10 | Q17: 0.70 ± 0.04 | R17: 30 ± 3 | S17: 56 ± 7 | V17: Layou | W17: 70 | X17: 8.21 | Y17: 0.3 | Z17: 5.57 | AA17: 79.6 | AB17: 2511
A18: S7 | B18: 18.1269 | C18: −66.9681 | D18: 193 | E18: 24.1 | F18: 82 | G18: 6.7 | H18: 29 | I18: 464 | J18: 72.9 ± 2.8 | K18: 110 ± 3 | L18: 60.0 ± 2.3 | M18: 90.9 ± 2.4 | N18: 0.34 ± 0.25 | O18: 0.45 ± 0.29 | P18: 0.51 ± 0.57 | Q18: 0.23 ± 0.19 | R18: 49 ± 5 | S18: 60 ± 6 | V18: St. Joseph’s River | W18: 3.4 | X18: 0.03 | Y18: 0.0002 | Z18: 0.0201 | AA18: 5.9 | AB18: 186
A19: S8 | B19: 18.1277 | C19: −66.9815 | D19: 190 | E19: 24.2 | F19: 78 | G19: 4.5 | H19: 29 | I19: 460 | J19: 67.0 ± 1.6 | K19: 103 ± 2 | L19: 52.1 ± 1.2 | M19: 80.0 ± 1.4 | N19: 0.75 ± 0.10 | O19: 0.78 ± 0.13 | P19: 3.03 ± 1.69 | Q19: 1.09 ± 0.59 | R19: 107 ± 11 | S19: 138 ± 15 | V19: Bateli River | W19: 12 | X19: 0.41 | Y19: 0.19 | Z19: 0.337 | AA19: 28.1 | AB19: 885
A20: S11 | B20: 18.1417 | C20: −66.9987 | D20: 221 | E20: 23.7 | F20: 128 | G20: 1.6 | H20: 29 | I20: 546 | J20: 74.0 ± 1.8 | K20: 112 ± 2 | L20: 94.8 ± 2.3 | M20: 143 ± 2 | N20: 0.69 ± 0.01 | O20: 0.79 ± 0.01 | P20: 2.19 ± 0.08 | Q20: 0.80 ± 0.03 | R20: 41 ± 4 | S20: 32 ± 3 | V20: Dublanc | W20: 6.5 | X20: 0.42 | Y20: 0.25 | Z20: 0.363 | AA20: 55.9 | AB20: 1763
A21: S12 | B21: 18.1552 | C21: −67.0199 | D21: 219 | E21: 24.2 | F21: 125 | G21: 4.5 | H21: 26 | I21: 431 | J21: 62.2 ± 1.9 | K21: 98.7 ± 2.1 | L21: 77.6 ± 2.4 | M21: 123 ± 3 | N21: 0.76 ± 0.02 | O21: 0.88 ± 0.01 | P21: 3.08 ± 0.25 | Q21: 1.15 ± 0.08 | R21: 69 ± 6 | S21: 55 ± 5 | V21: Blenheim River | W21: 18 | X21: 1.6 | Y21: 0.4 | Z21: 1.2 | AA21: 66.7 | AB21: 2102
A22: S13 | B22: 18.1678 | C22: −67.0357 | D22: 213 | E22: 24.4 | F22: 114 | G22: 3.4 | H22: 28 | I22: 302 | J22: 63.1 ± 2.9 | K22: 98.7 ± 3.0 | L22: 72.3 ± 3.3 | M22: 113 ± 3 | N22: 0.67 ± 0.04 | O22: 0.77 ± 0.04 | P22: 2.06 ± 0.40 | Q22: 0.70 ± 0.12 | R22: 109 ± 11 | S22: 95 ± 10 | V22: Hampstead River | W22: 20 | X22: 3 | Y22: ~0.013 | Z22: 2 | AA22: 100.2 | AB22: 3160
A23: S14 | B23: 18.1658 | C23: −67.0027 | D23: 240 | E23: 23.6 | F23: 169 | G23: 3 | H23: 31 | I23: 528 | J23: 52.0 ± 1.2 | K23: 82.9 ± 1.4 | L23: 87.7 ± 2.1 | M23: 140 ± 2 | N23: 0.88 ± 0.02 | O23: 0.94 ± 0.01 | P23: 7.49 ± 1.16 | Q23: 2.54 ± 0.37 | R23: 53 ± 5 | S23: 31 ± 3 | V23: Pagua River DS | W23: 25 | X23: 1.5 | Y23: 0.5 | Z23: 1.17 | AA23: 46.7 | AB23: 1472
G24: =SUM(G13:G23) -> 47
A26: Gaillardet et al 1999
B27: yr—1 ) | C27: yr—1) | D27: yr—1) | E27: yr—1) | F27: X10^9 | G27: yr—1) | H27: yr—1) | I27: yr—1) | J27: yr—1) | M27: yr—1) | V27: Goldsmith et al. 2008
A28: Amazon | B28: 79.7 | C28: 13.2 | D28: 128 | E28: 320 | F28: =E28*(10^9) -> 320000000000 | G28: 67.7 | H28: 644 | I28: 6 | J28: 0 | K28: 153 | L28: 25 | M28: 158 | V28: River | W28: Mean annual flow (m³/s) | Y28: km3/yr
A29: Changjiang | B29: 9.5 | C29: 2.5 | D29: 29 | E29: 107 | F29: =E29*(10^9) -> 107000000000 | G29: 101 | H29: 997 | I29: 7 | J29: 0 | K29: 118 | L29: 65 | M29: 611 | V29: Waitara (DS) | W29: 34 | Y29: =W29*0.031556952 -> 1.0729364 | AA29: Waitara (ds) | AC29: 1.0729364
A30: Mississippi | B30: 11.4 | C30: 5.1 | D30: 60 | E30: 199 | F30: =E30*(10^9) -> 199000000000 | G30: 48.1 | H30: 436 | I30: 13 | J30: 44 | K30: 72 | L30: 24 | M30: 228 | V30: Manganui (DS) | W30: 19.1 | Y30: =W30*0.031556952 -> 0.60273778 | AA30: Manganui (ds) | AC30: 0.60273778
A31: Irrawady | B31: 29.5 | C31: 17.1 | D31: 165 | E31: 832 | F31: =E31*(10^9) -> 832000000000 | G31: 2.6 | H31: 24 | I31: 19 | J31: 67 | K31: 51 | L31: 125 | M31: 2250 | V31: Manganui (US) | W31: 1.5 | Y31: =W31*0.031556952 -> 0.047335428 | AA31: Manganui (us) | AC31: 0.047335428
A32: Ganges | B32: 14.7 | C32: 8.3 | D32: 130 | E32: 471 | F32: =E32*(10^9) -> 471000000000 | G32: 24.4 | H32: 236 | I32: 5 | J32: 19 | K32: 44 | L32: 42 | M32: 692 | V32: Waipuku | W32: — (no long-term gauge) | AA32: Mangamawhete | AC32: 0.018934171
A33: Yenisei | B33: 9.7 | C33: 3.2 | D33: 30 | E33: 169 | F33: =E33*(10^9) -> 169000000000 | G33: 22.1 | H33: 207 | I33: 8 | J33: 0 | K33: 40 | L33: 16 | M33: 145 | V33: Mangamawhete | W33: 0.6 | Y33: =W33*0.031556952 -> 0.018934171 | AA33: Waingongoro (us) | AC33: 0.088359466
A34: Mackenzie | B34: 3.2 | C34: 1.6 | D34: 19 | E34: 61 | F34: =E34*(10^9) -> 61000000000 | G34: 26.7 | H34: 242 | I34: 5 | J34: 11 | K34: 35 | L34: 19 | M34: 176 | V34: Waingongoro (US) | W34: 2.8 | Y34: =W34*0.031556952 -> 0.088359466 | AA34: Waingongoro (ds) | AC34: 0.22089866
A35: St. Lawrence | B35: 1.9 | C35: 0.8 | D35: 9 | E35: 28 | F35: =E35*(10^9) -> 28000000000 | G35: 26.5 | H35: 251 | I35: 5 | J35: 17 | K35: 33 | L35: 33 | M35: 290 | V35: Waingongoro (DS) | W35: 7 | Y35: =W35*0.031556952 -> 0.22089866 | AA35: Patea (us) | AC35: 0.16409615
A36: Lena | B36: 5.4 | C36: 1.7 | D36: 19 | E36: 86 | F36: =E36*(10^9) -> 86000000000 | G36: 20.5 | H36: 187 | I36: 9 | J36: 0 | K36: 35 | L36: 14 | M36: 110 | V36: Patea (US) | W36: 5.2 | Y36: =W36*0.031556952 -> 0.16409615 | AA36: Waitara (us) | AC36: 0.73527698
A37: Xijiang | B37: 4 | C37: 0.7 | D37: 9 | E37: 24 | F37: =E37*(10^9) -> 24000000000 | G37: 30.2 | H37: 283 | I37: 2 | J37: 6 | K37: 36 | L37: 82 | M37: 715 | V37: Waitara (US) | W37: 23.3 | Y37: =W37*0.031556952 -> 0.73527698 | AA37: Kai-Iwi | AC37: 0.047335428
A38: Ob | B38: 2.4 | C38: 1 | D38: 11 | E38: 57 | F38: =E38*(10^9) -> 57000000000 | G38: 21.9 | H38: 217 | I38: 5 | J38: 26 | K38: 30 | L38: 10 | M38: 100 | V38: Waitotara | W38: — | AA38: Whanganui | AC38: 6.7531877
A39: Brahmaputra | B39: 6 | C39: 1.5 | D39: 19 | E39: 87 | F39: =E39*(10^9) -> 87000000000 | G39: 20.5 | H39: 199 | I39: 0 | J39: 0 | K39: 27 | L39: 46 | M39: 493 | V39: Kai-Iwi | W39: 1.5 | Y39: =W39*0.031556952 -> 0.047335428 | AA39: Whangaehu | AC39: 1.2559667
A40: Parana | B40: 13.9 | C40: 3.4 | D40: 69 | E40: 263 | F40: =E40*(10^9) -> 263000000000 | G40: 4.2 | H40: 51 | I40: 7 | J40: 31 | K40: 26 | L40: 9 | M40: 124 | V40: Maikirikiri | W40: — | AA40: Rangitikei | AC40: 1.988088
A41: Mekong | B41: 11.4 | C41: 4.9 | D41: 57 | E41: 194 | F41: =E41*(10^9) -> 194000000000 | G41: 44.3 | H41: 409 | I41: 17 | J41: 65 | K41: 72 | L41: 91 | M41: 839 | V41: Upokongaro | W41: — | AA41: Otaki | AC41: 1.0098225
A42: Congo–Zaire | B42: 15.6 | C42: 3.1 | D42: 34 | E42: 201 | F42: =E42*(10^9) -> 201000000000 | G42: 6.2 | H42: 51 | I42: 1 | J42: 0 | K42: 22 | L42: 6 | M42: 68 | V42: Whanganui | W42: 214 | Y42: =W42*0.031556952 -> 6.7531877
A43: Rhine | B43: 0.7 | C43: 0.3 | D43: 5 | E43: 14 | F43: =E43*(10^9) -> 14000000000 | G43: 10.3 | H43: 108 | I43: 1 | J43: 0 | K43: 12 | L43: 53 | M43: 542 | V43: Whangaehu | W43: 39.8 | Y43: =W43*0.031556952 -> 1.2559667
A44: Yukon | B44: 2.7 | C44: 0.9 | D44: 13 | E44: 29 | F44: =E44*(10^9) -> 29000000000 | G44: 17.3 | H44: 164 | I44: 0 | J44: 0 | K44: 20 | L44: 24 | M44: 227 | V44: Rangitikei | W44: 63 | Y44: =W44*0.031556952 -> 1.988088
A45: Orinoco | B45: 10.5 | C45: 2.5 | D45: 29 | E45: 76 | F45: =E45*(10^9) -> 76000000000 | G45: 6 | H45: 55 | I45: 0 | J45: 0 | K45: 16 | L45: 15 | M45: 119 | V45: Otaki | W45: 32 | Y45: =W45*0.031556952 -> 1.0098225
A46: Magdalena | B46: 3.6 | C46: 0.5 | D46: 7 | E46: 15 | F46: =E46*(10^9) -> 15000000000 | G46: 8.7 | H46: 82 | I46: 7 | J46: 33 | K46: 19 | L46: 81 | M46: 554
A47: Columbia | B47: 4.6 | C47: 1.9 | D47: 30 | E47: 61 | F47: =E47*(10^9) -> 61000000000 | G47: 9.8 | H47: 90 | I47: 1 | J47: 5 | K47: 16 | L47: 23 | M47: 233
A48: Indus | B48: 3.5 | C48: 1.6 | D48: 19 | E48: 54 | F48: =E48*(10^9) -> 54000000000 | G48: 6.6 | H48: 59 | I48: 6 | J48: 21 | K48: 16 | L48: 18 | M48: 146
A49: Don | B49: 6 | C49: 4.4 | D49: 55 | E49: 48 | F49: =E49*(10^9) -> 48000000000 | G49: 2.6 | H49: 23 | I49: 0 | J49: 0 | K49: 9 | L49: 20 | M49: 169
A50: Nelson | B50: 1.4 | C50: 0.9 | D50: 10 | E50: 43 | F50: =E50*(10^9) -> 43000000000 | G50: 7.2 | H50: 65 | I50: 4 | J50: 15 | K50: 12 | L50: 11 | M50: 109
A51: N. Dvina | B51: 0.7 | C51: 0.3 | D51: 4 | E51: 9 | F51: =E51*(10^9) -> 9000000000 | G51: 8 | H51: 69 | I51: 1 | J51: 3 | K51: 10 | L51: 28 | M51: 232 | V51: Frondini 2008
...

Sheet TO_CSV
A1: Location description | B1: location | C1: subgroup | D1: area_km2 | E1: co2_cons_mol_yr | F1: co2_cons_mol_km2_yr | G1: annual_discharge_km3_yr | H1: runoff_mm_yr
A2: Irrawady | C2: major | D2: 410000 | E2: 832000000000 | F2: 2029268.3 | G2: 486 | H2: 1185
A3: Purari | C3: major | D3: 30600 | E3: 37000000000 | F3: 1209150.3 | G3: 84.13 | H3: 2749
A4: Narmada | C4: major | D4: 102000 | E4: 95000000000 | F4: 931372.55 | G4: 39 | H4: 382
A5: Sepik | C5: major | D5: 78700 | E5: 72000000000 | F5: 914866.58 | G5: 120 | H5: 1525
A6: Rhone | C6: major | D6: 95600 | E6: 4700000000 | F6: 49163.18 | G6: 54 | H6: 565
A7: Cauveri | C7: major | D7: 88000 | E7: 56000000000 | F7: 636363.64 | G7: 21 | H7: 239
A8: Ganges | C8: major | D8: 1050000 | E8: 471000000000 | F8: 448571.43 | G8: 493 | H8: 470
A9: Wisla | C9: major | D9: 198000 | G9: 32.5 | H9: 164
A10: Rhine | C10: major | D10: 224000 | E10: 14000000000 | F10: 62500 | G10: 69.4 | H10: 310
A11: Brahmaputra | C11: major | D11: 580000 | E11: 87000000000 | F11: 150000 | G11: 510 | H11: 879
A12: Magdalena | C12: major | D12: 235000 | E12: 15000000000 | F12: 63829.787 | G12: 237 | H12: 1009
A13: Danube | C13: major | D13: 817000 | G13: 207 | H13: 253
A14: Xijiang | C14: major | D14: 437000 | E14: 24000000000 | F14: 54919.908 | G14: 363 | H14: 831
A15: Weser | C15: major | D15: 46000 | G15: 10.6 | H15: 230
A16: Kikori | C16: major | D16: 13200 | E16: 2500000000 | F16: 189393.94 | G16: 40.06 | H16: 3035
A17: Uruguay | C17: major | D17: 240000 | E17: 38900000000 | F17: 162083.33 | G17: 145 | H17: 604
A18: Krishna | C18: major | D18: 259000 | E18: 41000000000 | F18: 158301.16 | G18: 30 | H18: 116
A19: N. Dvina | C19: major | D19: 348000 | E19: 9000000000 | F19: 25862.069 | G19: 110 | H19: 316
A20: Kuskokwin | C20: major | D20: 123000 | E20: 12300000000 | F20: 100000 | G20: 59.9 | H20: 487
A21: Limpopo | C21: major | D21: 440000 | E21: 42400000000 | F21: 96363.636 | G21: 26 | H21: 59
A22: Ob | C22: major | D22: 2990000 | E22: 57000000000 | F22: 19063.545 | G22: 404 | H22: 135
A23: Salween | C23: major | D23: 325000 | G23: 211 | H23: 649
A24: Don | C24: major | D24: 420000 | E24: 48000000000 | F24: 114285.71 | G24: 28.9 | H24: 69
A25: Parana | C25: major | D25: 2780000 | E25: 263000000000 | F25: 94604.317 | G25: 568 | H25: 204
A26: Columbia | C26: major | D26: 669000 | E26: 61000000000 | F26: 91180.867 | G26: 236 | H26: 353
A27: Mississippi | C27: major | D27: 2980000 | E27: 199000000000 | F27: 66778.523 | G27: 580 | H27: 195
A28: Huanghe | C28: major | D28: 752000 | E28: 62000000000 | F28: 82446.809 | G28: 41 | H28: 55
A29: Changjiang | C29: major | D29: 1810000 | E29: 107000000000 | F29: 59116.022 | G29: 928 | H29: 513
A30: Orinoco | C30: major | D30: 1100000 | E30: 76000000000 | F30: 69090.909 | G30: 1135 | H30: 1032
A31: Nelson | C31: major | D31: 1130000 | E31: 43000000000 | F31: 38053.097 | G31: 89.3 | H31: 79
A32: Amazon | C32: major | D32: 6110000 | E32: 320000000000 | F32: 52373.159 | G32: 6590 | H32: 1078
A33: Mackenzie | C33: major | D33: 1790000 | E33: 61000000000 | F33: 34078.212 | G33: 308 | H33: 172
A34: Indus | C34: major | D34: 916000 | E34: 54000000000 | F34: 58951.965 | G34: 90 | H34: 98
A35: Kolima | C35: major | D35: 660000 | E35: 29000000000 | F35: 43939.394 | G35: 132 | H35: 200
... A47: Mekong | C47: major | D47: 795000 | E47: 194000000000 | F47: 244025.16 | G47: 467 | H47: 587
A48: Godavari | C48: major | D48: 313000 | G48: 105 | H48: 335
A49: Seine | C49: major | D49: 78600 | E49: 1000000000 | F49: 12722.646 | G49: 12.9 | H49: 164
A50: Amur | C50: major | D50: 1860000 | E50: 33000000000 | F50: 17741.935 | G50: 344 | H50: 185
A51: Congo–Zaire | C51: major | D51: 3700000 | E51: 201000000000 | F51: 54324.324 | G51: 1200 | H51: 324
...
